{"trial_id": "0", "hyperparameters": {"space": [{"class_name": "Choice", "config": {"name": "optimizer", "default": "SGD", "conditions": [], "values": ["SGD", "Adam"], "ordered": false}}], "values": {"optimizer": "SGD"}}, "metrics": {"metrics": {}}, "score": null, "best_step": 0, "status": "FAILED", "message": "Traceback (most recent call last):\n  File \"/home/flavio/.conda/envs/tf/lib/python3.10/site-packages/keras_tuner/engine/base_tuner.py\", line 270, in _try_run_and_update_trial\n    self._run_and_update_trial(trial, *fit_args, **fit_kwargs)\n  File \"/home/flavio/.conda/envs/tf/lib/python3.10/site-packages/keras_tuner/engine/base_tuner.py\", line 235, in _run_and_update_trial\n    results = self.run_trial(trial, *fit_args, **fit_kwargs)\n  File \"/home/flavio/.conda/envs/tf/lib/python3.10/site-packages/keras_tuner/engine/tuner.py\", line 287, in run_trial\n    obj_value = self._build_and_fit_model(trial, *args, **copied_kwargs)\n  File \"/home/flavio/.conda/envs/tf/lib/python3.10/site-packages/keras_tuner/engine/tuner.py\", line 214, in _build_and_fit_model\n    results = self.hypermodel.fit(hp, model, *args, **kwargs)\n  File \"/home/flavio/.conda/envs/tf/lib/python3.10/site-packages/keras_tuner/engine/hypermodel.py\", line 144, in fit\n    return model.fit(*args, **kwargs)\n  File \"/home/flavio/.conda/envs/tf/lib/python3.10/site-packages/keras/src/utils/traceback_utils.py\", line 70, in error_handler\n    raise e.with_traceback(filtered_tb) from None\n  File \"/tmp/__autograph_generated_filex5q4uidk.py\", line 15, in tf__train_function\n    retval_ = ag__.converted_call(ag__.ld(step_function), (ag__.ld(self), ag__.ld(iterator)), None, fscope)\nValueError: in user code:\n\n    File \"/home/flavio/.conda/envs/tf/lib/python3.10/site-packages/keras/src/engine/training.py\", line 1338, in train_function  *\n        return step_function(self, iterator)\n    File \"/home/flavio/.conda/envs/tf/lib/python3.10/site-packages/keras/src/engine/training.py\", line 1322, in step_function  **\n        outputs = model.distribute_strategy.run(run_step, args=(data,))\n    File \"/home/flavio/.conda/envs/tf/lib/python3.10/site-packages/keras/src/engine/training.py\", line 1303, in run_step  **\n        outputs = model.train_step(data)\n    File \"/home/flavio/.conda/envs/tf/lib/python3.10/site-packages/keras/src/engine/training.py\", line 1080, in train_step\n        y_pred = self(x, training=True)\n    File \"/home/flavio/.conda/envs/tf/lib/python3.10/site-packages/keras/src/utils/traceback_utils.py\", line 70, in error_handler\n        raise e.with_traceback(filtered_tb) from None\n    File \"/home/flavio/.conda/envs/tf/lib/python3.10/site-packages/keras/src/engine/input_spec.py\", line 298, in assert_input_compatibility\n        raise ValueError(\n\n    ValueError: Input 0 of layer \"sequential\" is incompatible with the layer: expected shape=(None, 20), found shape=(32, 784)\n\n"}